[2025-06-17 23:18:28 +0200] [317607] [INFO] Starting gunicorn 23.0.0
[2025-06-17 23:18:28 +0200] [317607] [INFO] Listening at: http://0.0.0.0:8000 (317607)
[2025-06-17 23:18:28 +0200] [317607] [INFO] Using worker: sync
[2025-06-17 23:18:28 +0200] [317609] [INFO] Booting worker with pid: 317609
[2025-06-17 23:51:52 +0200] [317609] [ERROR] Error handling request /login/
Traceback (most recent call last):
  File "/home/markmur88/envAPP/lib/python3.13/site-packages/django/core/handlers/exception.py", line 55, in inner
    response = get_response(request)
  File "/home/markmur88/envAPP/lib/python3.13/site-packages/debug_toolbar/middleware.py", line 114, in __call__
    if not show_toolbar(request) or DebugToolbar.is_toolbar_request(request):
                                    ~~~~~~~~~~~~~~~~~~~~~~~~~~~~~~~^^^^^^^^^
  File "/home/markmur88/envAPP/lib/python3.13/site-packages/debug_toolbar/toolbar.py", line 185, in is_toolbar_request
    resolver_match = request.resolver_match or resolve(
                                               ~~~~~~~^
        request.path_info, getattr(request, "urlconf", None)
        ^^^^^^^^^^^^^^^^^^^^^^^^^^^^^^^^^^^^^^^^^^^^^^^^^^^^
    )
    ^
  File "/home/markmur88/envAPP/lib/python3.13/site-packages/django/urls/base.py", line 25, in resolve
    return get_resolver(urlconf).resolve(path)
           ~~~~~~~~~~~~~~~~~~~~~~~~~~~~~^^^^^^
  File "/home/markmur88/envAPP/lib/python3.13/site-packages/django/urls/resolvers.py", line 666, in resolve
    for pattern in self.url_patterns:
                   ^^^^^^^^^^^^^^^^^
  File "/home/markmur88/envAPP/lib/python3.13/site-packages/django/utils/functional.py", line 47, in __get__
    res = instance.__dict__[self.name] = self.func(instance)
                                         ~~~~~~~~~^^^^^^^^^^
  File "/home/markmur88/envAPP/lib/python3.13/site-packages/django/urls/resolvers.py", line 718, in url_patterns
    patterns = getattr(self.urlconf_module, "urlpatterns", self.urlconf_module)
                       ^^^^^^^^^^^^^^^^^^^
  File "/home/markmur88/envAPP/lib/python3.13/site-packages/django/utils/functional.py", line 47, in __get__
    res = instance.__dict__[self.name] = self.func(instance)
                                         ~~~~~~~~~^^^^^^^^^^
  File "/home/markmur88/envAPP/lib/python3.13/site-packages/django/urls/resolvers.py", line 711, in urlconf_module
    return import_module(self.urlconf_name)
  File "/usr/lib/python3.13/importlib/__init__.py", line 88, in import_module
    return _bootstrap._gcd_import(name[level:], package, level)
           ~~~~~~~~~~~~~~~~~~~~~~^^^^^^^^^^^^^^^^^^^^^^^^^^^^^^
  File "<frozen importlib._bootstrap>", line 1387, in _gcd_import
  File "<frozen importlib._bootstrap>", line 1360, in _find_and_load
  File "<frozen importlib._bootstrap>", line 1331, in _find_and_load_unlocked
  File "<frozen importlib._bootstrap>", line 935, in _load_unlocked
  File "<frozen importlib._bootstrap_external>", line 1026, in exec_module
  File "<frozen importlib._bootstrap>", line 488, in _call_with_frames_removed
  File "/home/markmur88/api_bank_h2/config/urls.py", line 26, in <module>
    from api.gpt4.views import oauth2_authorize, oauth2_callback
  File "/home/markmur88/api_bank_h2/api/gpt4/views.py", line 1319, in <module>
    from .conexion_banco_refactor import (
    ...<3 lines>...
    )
  File "/home/markmur88/api_bank_h2/api/gpt4/conexion_banco_refactor.py", line 203, in <module>
    connector = BankConnector(config=config, logger=logger)
  File "/home/markmur88/api_bank_h2/api/gpt4/conexion_banco_refactor.py", line 102, in __init__
    self._init_client()
    ~~~~~~~~~~~~~~~~~^^
  File "/home/markmur88/api_bank_h2/api/gpt4/conexion_banco_refactor.py", line 110, in _init_client
    dns_bank_raw = self.config.get('DNS_BANCO', required=True)
  File "/home/markmur88/api_bank_h2/api/gpt4/conexion_banco_refactor.py", line 34, in get
    raise ConfigError(f"Missing required config: {name}")
api.gpt4.conexion_banco_refactor.ConfigError: Missing required config: BANK_DNS_BANCO

During handling of the above exception, another exception occurred:

Traceback (most recent call last):
  File "/home/markmur88/envAPP/lib/python3.13/site-packages/django/core/handlers/exception.py", line 55, in inner
    response = get_response(request)
  File "/home/markmur88/envAPP/lib/python3.13/site-packages/django/utils/deprecation.py", line 120, in __call__
    response = response or self.get_response(request)
                           ~~~~~~~~~~~~~~~~~^^^^^^^^^
  File "/home/markmur88/envAPP/lib/python3.13/site-packages/django/core/handlers/exception.py", line 57, in inner
    response = response_for_exception(request, exc)
  File "/home/markmur88/envAPP/lib/python3.13/site-packages/django/core/handlers/exception.py", line 140, in response_for_exception
    response = handle_uncaught_exception(
        request, get_resolver(get_urlconf()), sys.exc_info()
    )
  File "/home/markmur88/envAPP/lib/python3.13/site-packages/django/core/handlers/exception.py", line 181, in handle_uncaught_exception
    return debug.technical_500_response(request, *exc_info)
           ~~~~~~~~~~~~~~~~~~~~~~~~~~~~^^^^^^^^^^^^^^^^^^^^
  File "/home/markmur88/envAPP/lib/python3.13/site-packages/django/views/debug.py", line 69, in technical_500_response
    html = reporter.get_traceback_html()
  File "/home/markmur88/envAPP/lib/python3.13/site-packages/django/views/debug.py", line 428, in get_traceback_html
    c = Context(self.get_traceback_data(), use_l10n=False)
                ~~~~~~~~~~~~~~~~~~~~~~~^^
  File "/home/markmur88/envAPP/lib/python3.13/site-packages/django/views/debug.py", line 411, in get_traceback_data
    c["raising_view_name"] = get_caller(self.request)
                             ~~~~~~~~~~^^^^^^^^^^^^^^
  File "/home/markmur88/envAPP/lib/python3.13/site-packages/django/views/debug.py", line 102, in get_caller
    resolver_match = resolve(request.path)
  File "/home/markmur88/envAPP/lib/python3.13/site-packages/django/urls/base.py", line 25, in resolve
    return get_resolver(urlconf).resolve(path)
           ~~~~~~~~~~~~~~~~~~~~~~~~~~~~~^^^^^^
  File "/home/markmur88/envAPP/lib/python3.13/site-packages/django/urls/resolvers.py", line 666, in resolve
    for pattern in self.url_patterns:
                   ^^^^^^^^^^^^^^^^^
  File "/home/markmur88/envAPP/lib/python3.13/site-packages/django/utils/functional.py", line 47, in __get__
    res = instance.__dict__[self.name] = self.func(instance)
                                         ~~~~~~~~~^^^^^^^^^^
  File "/home/markmur88/envAPP/lib/python3.13/site-packages/django/urls/resolvers.py", line 718, in url_patterns
    patterns = getattr(self.urlconf_module, "urlpatterns", self.urlconf_module)
                       ^^^^^^^^^^^^^^^^^^^
  File "/home/markmur88/envAPP/lib/python3.13/site-packages/django/utils/functional.py", line 47, in __get__
    res = instance.__dict__[self.name] = self.func(instance)
                                         ~~~~~~~~~^^^^^^^^^^
  File "/home/markmur88/envAPP/lib/python3.13/site-packages/django/urls/resolvers.py", line 711, in urlconf_module
    return import_module(self.urlconf_name)
  File "/usr/lib/python3.13/importlib/__init__.py", line 88, in import_module
    return _bootstrap._gcd_import(name[level:], package, level)
           ~~~~~~~~~~~~~~~~~~~~~~^^^^^^^^^^^^^^^^^^^^^^^^^^^^^^
  File "<frozen importlib._bootstrap>", line 1387, in _gcd_import
  File "<frozen importlib._bootstrap>", line 1360, in _find_and_load
  File "<frozen importlib._bootstrap>", line 1331, in _find_and_load_unlocked
  File "<frozen importlib._bootstrap>", line 935, in _load_unlocked
  File "<frozen importlib._bootstrap_external>", line 1026, in exec_module
  File "<frozen importlib._bootstrap>", line 488, in _call_with_frames_removed
  File "/home/markmur88/api_bank_h2/config/urls.py", line 26, in <module>
    from api.gpt4.views import oauth2_authorize, oauth2_callback
  File "/home/markmur88/api_bank_h2/api/gpt4/views.py", line 1319, in <module>
    from .conexion_banco_refactor import (
    ...<3 lines>...
    )
  File "/home/markmur88/api_bank_h2/api/gpt4/conexion_banco_refactor.py", line 203, in <module>
    connector = BankConnector(config=config, logger=logger)
  File "/home/markmur88/api_bank_h2/api/gpt4/conexion_banco_refactor.py", line 102, in __init__
    self._init_client()
    ~~~~~~~~~~~~~~~~~^^
  File "/home/markmur88/api_bank_h2/api/gpt4/conexion_banco_refactor.py", line 110, in _init_client
    dns_bank_raw = self.config.get('DNS_BANCO', required=True)
  File "/home/markmur88/api_bank_h2/api/gpt4/conexion_banco_refactor.py", line 34, in get
    raise ConfigError(f"Missing required config: {name}")
api.gpt4.conexion_banco_refactor.ConfigError: Missing required config: BANK_DNS_BANCO

During handling of the above exception, another exception occurred:

Traceback (most recent call last):
  File "/home/markmur88/envAPP/lib/python3.13/site-packages/django/core/handlers/exception.py", line 55, in inner
    response = get_response(request)
  File "/home/markmur88/envAPP/lib/python3.13/site-packages/whitenoise/middleware.py", line 123, in __call__
    return self.get_response(request)
           ~~~~~~~~~~~~~~~~~^^^^^^^^^
  File "/home/markmur88/envAPP/lib/python3.13/site-packages/django/core/handlers/exception.py", line 57, in inner
    response = response_for_exception(request, exc)
  File "/home/markmur88/envAPP/lib/python3.13/site-packages/django/core/handlers/exception.py", line 140, in response_for_exception
    response = handle_uncaught_exception(
        request, get_resolver(get_urlconf()), sys.exc_info()
    )
  File "/home/markmur88/envAPP/lib/python3.13/site-packages/django/core/handlers/exception.py", line 181, in handle_uncaught_exception
    return debug.technical_500_response(request, *exc_info)
           ~~~~~~~~~~~~~~~~~~~~~~~~~~~~^^^^^^^^^^^^^^^^^^^^
  File "/home/markmur88/envAPP/lib/python3.13/site-packages/django/views/debug.py", line 69, in technical_500_response
    html = reporter.get_traceback_html()
  File "/home/markmur88/envAPP/lib/python3.13/site-packages/django/views/debug.py", line 428, in get_traceback_html
    c = Context(self.get_traceback_data(), use_l10n=False)
                ~~~~~~~~~~~~~~~~~~~~~~~^^
  File "/home/markmur88/envAPP/lib/python3.13/site-packages/django/views/debug.py", line 411, in get_traceback_data
    c["raising_view_name"] = get_caller(self.request)
                             ~~~~~~~~~~^^^^^^^^^^^^^^
  File "/home/markmur88/envAPP/lib/python3.13/site-packages/django/views/debug.py", line 102, in get_caller
    resolver_match = resolve(request.path)
  File "/home/markmur88/envAPP/lib/python3.13/site-packages/django/urls/base.py", line 25, in resolve
    return get_resolver(urlconf).resolve(path)
           ~~~~~~~~~~~~~~~~~~~~~~~~~~~~~^^^^^^
  File "/home/markmur88/envAPP/lib/python3.13/site-packages/django/urls/resolvers.py", line 666, in resolve
    for pattern in self.url_patterns:
                   ^^^^^^^^^^^^^^^^^
  File "/home/markmur88/envAPP/lib/python3.13/site-packages/django/utils/functional.py", line 47, in __get__
    res = instance.__dict__[self.name] = self.func(instance)
                                         ~~~~~~~~~^^^^^^^^^^
  File "/home/markmur88/envAPP/lib/python3.13/site-packages/django/urls/resolvers.py", line 718, in url_patterns
    patterns = getattr(self.urlconf_module, "urlpatterns", self.urlconf_module)
                       ^^^^^^^^^^^^^^^^^^^
  File "/home/markmur88/envAPP/lib/python3.13/site-packages/django/utils/functional.py", line 47, in __get__
    res = instance.__dict__[self.name] = self.func(instance)
                                         ~~~~~~~~~^^^^^^^^^^
  File "/home/markmur88/envAPP/lib/python3.13/site-packages/django/urls/resolvers.py", line 711, in urlconf_module
    return import_module(self.urlconf_name)
  File "/usr/lib/python3.13/importlib/__init__.py", line 88, in import_module
    return _bootstrap._gcd_import(name[level:], package, level)
           ~~~~~~~~~~~~~~~~~~~~~~^^^^^^^^^^^^^^^^^^^^^^^^^^^^^^
  File "<frozen importlib._bootstrap>", line 1387, in _gcd_import
  File "<frozen importlib._bootstrap>", line 1360, in _find_and_load
  File "<frozen importlib._bootstrap>", line 1331, in _find_and_load_unlocked
  File "<frozen importlib._bootstrap>", line 935, in _load_unlocked
  File "<frozen importlib._bootstrap_external>", line 1026, in exec_module
  File "<frozen importlib._bootstrap>", line 488, in _call_with_frames_removed
  File "/home/markmur88/api_bank_h2/config/urls.py", line 26, in <module>
    from api.gpt4.views import oauth2_authorize, oauth2_callback
  File "/home/markmur88/api_bank_h2/api/gpt4/views.py", line 1319, in <module>
    from .conexion_banco_refactor import (
    ...<3 lines>...
    )
  File "/home/markmur88/api_bank_h2/api/gpt4/conexion_banco_refactor.py", line 203, in <module>
    connector = BankConnector(config=config, logger=logger)
  File "/home/markmur88/api_bank_h2/api/gpt4/conexion_banco_refactor.py", line 102, in __init__
    self._init_client()
    ~~~~~~~~~~~~~~~~~^^
  File "/home/markmur88/api_bank_h2/api/gpt4/conexion_banco_refactor.py", line 110, in _init_client
    dns_bank_raw = self.config.get('DNS_BANCO', required=True)
  File "/home/markmur88/api_bank_h2/api/gpt4/conexion_banco_refactor.py", line 34, in get
    raise ConfigError(f"Missing required config: {name}")
api.gpt4.conexion_banco_refactor.ConfigError: Missing required config: BANK_DNS_BANCO

During handling of the above exception, another exception occurred:

Traceback (most recent call last):
  File "/home/markmur88/envAPP/lib/python3.13/site-packages/gunicorn/workers/sync.py", line 134, in handle
    self.handle_request(listener, req, client, addr)
    ~~~~~~~~~~~~~~~~~~~^^^^^^^^^^^^^^^^^^^^^^^^^^^^^
  File "/home/markmur88/envAPP/lib/python3.13/site-packages/gunicorn/workers/sync.py", line 177, in handle_request
    respiter = self.wsgi(environ, resp.start_response)
  File "/home/markmur88/envAPP/lib/python3.13/site-packages/django/core/handlers/wsgi.py", line 124, in __call__
    response = self.get_response(request)
  File "/home/markmur88/envAPP/lib/python3.13/site-packages/django/core/handlers/base.py", line 140, in get_response
    response = self._middleware_chain(request)
  File "/home/markmur88/envAPP/lib/python3.13/site-packages/django/core/handlers/exception.py", line 57, in inner
    response = response_for_exception(request, exc)
  File "/home/markmur88/envAPP/lib/python3.13/site-packages/django/core/handlers/exception.py", line 140, in response_for_exception
    response = handle_uncaught_exception(
        request, get_resolver(get_urlconf()), sys.exc_info()
    )
  File "/home/markmur88/envAPP/lib/python3.13/site-packages/django/core/handlers/exception.py", line 181, in handle_uncaught_exception
    return debug.technical_500_response(request, *exc_info)
           ~~~~~~~~~~~~~~~~~~~~~~~~~~~~^^^^^^^^^^^^^^^^^^^^
  File "/home/markmur88/envAPP/lib/python3.13/site-packages/django/views/debug.py", line 69, in technical_500_response
    html = reporter.get_traceback_html()
  File "/home/markmur88/envAPP/lib/python3.13/site-packages/django/views/debug.py", line 428, in get_traceback_html
    c = Context(self.get_traceback_data(), use_l10n=False)
                ~~~~~~~~~~~~~~~~~~~~~~~^^
  File "/home/markmur88/envAPP/lib/python3.13/site-packages/django/views/debug.py", line 411, in get_traceback_data
    c["raising_view_name"] = get_caller(self.request)
                             ~~~~~~~~~~^^^^^^^^^^^^^^
  File "/home/markmur88/envAPP/lib/python3.13/site-packages/django/views/debug.py", line 102, in get_caller
    resolver_match = resolve(request.path)
  File "/home/markmur88/envAPP/lib/python3.13/site-packages/django/urls/base.py", line 25, in resolve
    return get_resolver(urlconf).resolve(path)
           ~~~~~~~~~~~~~~~~~~~~~~~~~~~~~^^^^^^
  File "/home/markmur88/envAPP/lib/python3.13/site-packages/django/urls/resolvers.py", line 666, in resolve
    for pattern in self.url_patterns:
                   ^^^^^^^^^^^^^^^^^
  File "/home/markmur88/envAPP/lib/python3.13/site-packages/django/utils/functional.py", line 47, in __get__
    res = instance.__dict__[self.name] = self.func(instance)
                                         ~~~~~~~~~^^^^^^^^^^
  File "/home/markmur88/envAPP/lib/python3.13/site-packages/django/urls/resolvers.py", line 718, in url_patterns
    patterns = getattr(self.urlconf_module, "urlpatterns", self.urlconf_module)
                       ^^^^^^^^^^^^^^^^^^^
  File "/home/markmur88/envAPP/lib/python3.13/site-packages/django/utils/functional.py", line 47, in __get__
    res = instance.__dict__[self.name] = self.func(instance)
                                         ~~~~~~~~~^^^^^^^^^^
  File "/home/markmur88/envAPP/lib/python3.13/site-packages/django/urls/resolvers.py", line 711, in urlconf_module
    return import_module(self.urlconf_name)
  File "/usr/lib/python3.13/importlib/__init__.py", line 88, in import_module
    return _bootstrap._gcd_import(name[level:], package, level)
           ~~~~~~~~~~~~~~~~~~~~~~^^^^^^^^^^^^^^^^^^^^^^^^^^^^^^
  File "<frozen importlib._bootstrap>", line 1387, in _gcd_import
  File "<frozen importlib._bootstrap>", line 1360, in _find_and_load
  File "<frozen importlib._bootstrap>", line 1331, in _find_and_load_unlocked
  File "<frozen importlib._bootstrap>", line 935, in _load_unlocked
  File "<frozen importlib._bootstrap_external>", line 1026, in exec_module
  File "<frozen importlib._bootstrap>", line 488, in _call_with_frames_removed
  File "/home/markmur88/api_bank_h2/config/urls.py", line 26, in <module>
    from api.gpt4.views import oauth2_authorize, oauth2_callback
  File "/home/markmur88/api_bank_h2/api/gpt4/views.py", line 1319, in <module>
    from .conexion_banco_refactor import (
    ...<3 lines>...
    )
  File "/home/markmur88/api_bank_h2/api/gpt4/conexion_banco_refactor.py", line 203, in <module>
    connector = BankConnector(config=config, logger=logger)
  File "/home/markmur88/api_bank_h2/api/gpt4/conexion_banco_refactor.py", line 102, in __init__
    self._init_client()
    ~~~~~~~~~~~~~~~~~^^
  File "/home/markmur88/api_bank_h2/api/gpt4/conexion_banco_refactor.py", line 110, in _init_client
    dns_bank_raw = self.config.get('DNS_BANCO', required=True)
  File "/home/markmur88/api_bank_h2/api/gpt4/conexion_banco_refactor.py", line 34, in get
    raise ConfigError(f"Missing required config: {name}")
api.gpt4.conexion_banco_refactor.ConfigError: Missing required config: BANK_DNS_BANCO
[2025-06-17 23:51:52 +0200] [317609] [ERROR] Error handling request /favicon.ico
Traceback (most recent call last):
  File "/home/markmur88/envAPP/lib/python3.13/site-packages/django/core/handlers/exception.py", line 55, in inner
    response = get_response(request)
  File "/home/markmur88/envAPP/lib/python3.13/site-packages/debug_toolbar/middleware.py", line 114, in __call__
    if not show_toolbar(request) or DebugToolbar.is_toolbar_request(request):
                                    ~~~~~~~~~~~~~~~~~~~~~~~~~~~~~~~^^^^^^^^^
  File "/home/markmur88/envAPP/lib/python3.13/site-packages/debug_toolbar/toolbar.py", line 185, in is_toolbar_request
    resolver_match = request.resolver_match or resolve(
                                               ~~~~~~~^
        request.path_info, getattr(request, "urlconf", None)
        ^^^^^^^^^^^^^^^^^^^^^^^^^^^^^^^^^^^^^^^^^^^^^^^^^^^^
    )
    ^
  File "/home/markmur88/envAPP/lib/python3.13/site-packages/django/urls/base.py", line 25, in resolve
    return get_resolver(urlconf).resolve(path)
           ~~~~~~~~~~~~~~~~~~~~~~~~~~~~~^^^^^^
  File "/home/markmur88/envAPP/lib/python3.13/site-packages/django/urls/resolvers.py", line 666, in resolve
    for pattern in self.url_patterns:
                   ^^^^^^^^^^^^^^^^^
  File "/home/markmur88/envAPP/lib/python3.13/site-packages/django/utils/functional.py", line 47, in __get__
    res = instance.__dict__[self.name] = self.func(instance)
                                         ~~~~~~~~~^^^^^^^^^^
  File "/home/markmur88/envAPP/lib/python3.13/site-packages/django/urls/resolvers.py", line 718, in url_patterns
    patterns = getattr(self.urlconf_module, "urlpatterns", self.urlconf_module)
                       ^^^^^^^^^^^^^^^^^^^
  File "/home/markmur88/envAPP/lib/python3.13/site-packages/django/utils/functional.py", line 47, in __get__
    res = instance.__dict__[self.name] = self.func(instance)
                                         ~~~~~~~~~^^^^^^^^^^
  File "/home/markmur88/envAPP/lib/python3.13/site-packages/django/urls/resolvers.py", line 711, in urlconf_module
    return import_module(self.urlconf_name)
  File "/usr/lib/python3.13/importlib/__init__.py", line 88, in import_module
    return _bootstrap._gcd_import(name[level:], package, level)
           ~~~~~~~~~~~~~~~~~~~~~~^^^^^^^^^^^^^^^^^^^^^^^^^^^^^^
  File "<frozen importlib._bootstrap>", line 1387, in _gcd_import
  File "<frozen importlib._bootstrap>", line 1360, in _find_and_load
  File "<frozen importlib._bootstrap>", line 1331, in _find_and_load_unlocked
  File "<frozen importlib._bootstrap>", line 935, in _load_unlocked
  File "<frozen importlib._bootstrap_external>", line 1026, in exec_module
  File "<frozen importlib._bootstrap>", line 488, in _call_with_frames_removed
  File "/home/markmur88/api_bank_h2/config/urls.py", line 26, in <module>
    from api.gpt4.views import oauth2_authorize, oauth2_callback
  File "/home/markmur88/api_bank_h2/api/gpt4/views.py", line 1319, in <module>
    from .conexion_banco_refactor import (
    ...<3 lines>...
    )
  File "/home/markmur88/api_bank_h2/api/gpt4/conexion_banco_refactor.py", line 203, in <module>
    connector = BankConnector(config=config, logger=logger)
  File "/home/markmur88/api_bank_h2/api/gpt4/conexion_banco_refactor.py", line 102, in __init__
    self._init_client()
    ~~~~~~~~~~~~~~~~~^^
  File "/home/markmur88/api_bank_h2/api/gpt4/conexion_banco_refactor.py", line 110, in _init_client
    dns_bank_raw = self.config.get('DNS_BANCO', required=True)
  File "/home/markmur88/api_bank_h2/api/gpt4/conexion_banco_refactor.py", line 34, in get
    raise ConfigError(f"Missing required config: {name}")
api.gpt4.conexion_banco_refactor.ConfigError: Missing required config: BANK_DNS_BANCO

During handling of the above exception, another exception occurred:

Traceback (most recent call last):
  File "/home/markmur88/envAPP/lib/python3.13/site-packages/django/core/handlers/exception.py", line 55, in inner
    response = get_response(request)
  File "/home/markmur88/envAPP/lib/python3.13/site-packages/django/utils/deprecation.py", line 120, in __call__
    response = response or self.get_response(request)
                           ~~~~~~~~~~~~~~~~~^^^^^^^^^
  File "/home/markmur88/envAPP/lib/python3.13/site-packages/django/core/handlers/exception.py", line 57, in inner
    response = response_for_exception(request, exc)
  File "/home/markmur88/envAPP/lib/python3.13/site-packages/django/core/handlers/exception.py", line 140, in response_for_exception
    response = handle_uncaught_exception(
        request, get_resolver(get_urlconf()), sys.exc_info()
    )
  File "/home/markmur88/envAPP/lib/python3.13/site-packages/django/core/handlers/exception.py", line 181, in handle_uncaught_exception
    return debug.technical_500_response(request, *exc_info)
           ~~~~~~~~~~~~~~~~~~~~~~~~~~~~^^^^^^^^^^^^^^^^^^^^
  File "/home/markmur88/envAPP/lib/python3.13/site-packages/django/views/debug.py", line 69, in technical_500_response
    html = reporter.get_traceback_html()
  File "/home/markmur88/envAPP/lib/python3.13/site-packages/django/views/debug.py", line 428, in get_traceback_html
    c = Context(self.get_traceback_data(), use_l10n=False)
                ~~~~~~~~~~~~~~~~~~~~~~~^^
  File "/home/markmur88/envAPP/lib/python3.13/site-packages/django/views/debug.py", line 411, in get_traceback_data
    c["raising_view_name"] = get_caller(self.request)
                             ~~~~~~~~~~^^^^^^^^^^^^^^
  File "/home/markmur88/envAPP/lib/python3.13/site-packages/django/views/debug.py", line 102, in get_caller
    resolver_match = resolve(request.path)
  File "/home/markmur88/envAPP/lib/python3.13/site-packages/django/urls/base.py", line 25, in resolve
    return get_resolver(urlconf).resolve(path)
           ~~~~~~~~~~~~~~~~~~~~~~~~~~~~~^^^^^^
  File "/home/markmur88/envAPP/lib/python3.13/site-packages/django/urls/resolvers.py", line 666, in resolve
    for pattern in self.url_patterns:
                   ^^^^^^^^^^^^^^^^^
  File "/home/markmur88/envAPP/lib/python3.13/site-packages/django/utils/functional.py", line 47, in __get__
    res = instance.__dict__[self.name] = self.func(instance)
                                         ~~~~~~~~~^^^^^^^^^^
  File "/home/markmur88/envAPP/lib/python3.13/site-packages/django/urls/resolvers.py", line 718, in url_patterns
    patterns = getattr(self.urlconf_module, "urlpatterns", self.urlconf_module)
                       ^^^^^^^^^^^^^^^^^^^
  File "/home/markmur88/envAPP/lib/python3.13/site-packages/django/utils/functional.py", line 47, in __get__
    res = instance.__dict__[self.name] = self.func(instance)
                                         ~~~~~~~~~^^^^^^^^^^
  File "/home/markmur88/envAPP/lib/python3.13/site-packages/django/urls/resolvers.py", line 711, in urlconf_module
    return import_module(self.urlconf_name)
  File "/usr/lib/python3.13/importlib/__init__.py", line 88, in import_module
    return _bootstrap._gcd_import(name[level:], package, level)
           ~~~~~~~~~~~~~~~~~~~~~~^^^^^^^^^^^^^^^^^^^^^^^^^^^^^^
  File "<frozen importlib._bootstrap>", line 1387, in _gcd_import
  File "<frozen importlib._bootstrap>", line 1360, in _find_and_load
  File "<frozen importlib._bootstrap>", line 1331, in _find_and_load_unlocked
  File "<frozen importlib._bootstrap>", line 935, in _load_unlocked
  File "<frozen importlib._bootstrap_external>", line 1026, in exec_module
  File "<frozen importlib._bootstrap>", line 488, in _call_with_frames_removed
  File "/home/markmur88/api_bank_h2/config/urls.py", line 26, in <module>
    from api.gpt4.views import oauth2_authorize, oauth2_callback
  File "/home/markmur88/api_bank_h2/api/gpt4/views.py", line 1319, in <module>
    from .conexion_banco_refactor import (
    ...<3 lines>...
    )
  File "/home/markmur88/api_bank_h2/api/gpt4/conexion_banco_refactor.py", line 203, in <module>
    connector = BankConnector(config=config, logger=logger)
  File "/home/markmur88/api_bank_h2/api/gpt4/conexion_banco_refactor.py", line 102, in __init__
    self._init_client()
    ~~~~~~~~~~~~~~~~~^^
  File "/home/markmur88/api_bank_h2/api/gpt4/conexion_banco_refactor.py", line 110, in _init_client
    dns_bank_raw = self.config.get('DNS_BANCO', required=True)
  File "/home/markmur88/api_bank_h2/api/gpt4/conexion_banco_refactor.py", line 34, in get
    raise ConfigError(f"Missing required config: {name}")
api.gpt4.conexion_banco_refactor.ConfigError: Missing required config: BANK_DNS_BANCO

During handling of the above exception, another exception occurred:

Traceback (most recent call last):
  File "/home/markmur88/envAPP/lib/python3.13/site-packages/django/core/handlers/exception.py", line 55, in inner
    response = get_response(request)
  File "/home/markmur88/envAPP/lib/python3.13/site-packages/whitenoise/middleware.py", line 123, in __call__
    return self.get_response(request)
           ~~~~~~~~~~~~~~~~~^^^^^^^^^
  File "/home/markmur88/envAPP/lib/python3.13/site-packages/django/core/handlers/exception.py", line 57, in inner
    response = response_for_exception(request, exc)
  File "/home/markmur88/envAPP/lib/python3.13/site-packages/django/core/handlers/exception.py", line 140, in response_for_exception
    response = handle_uncaught_exception(
        request, get_resolver(get_urlconf()), sys.exc_info()
    )
  File "/home/markmur88/envAPP/lib/python3.13/site-packages/django/core/handlers/exception.py", line 181, in handle_uncaught_exception
    return debug.technical_500_response(request, *exc_info)
           ~~~~~~~~~~~~~~~~~~~~~~~~~~~~^^^^^^^^^^^^^^^^^^^^
  File "/home/markmur88/envAPP/lib/python3.13/site-packages/django/views/debug.py", line 69, in technical_500_response
    html = reporter.get_traceback_html()
  File "/home/markmur88/envAPP/lib/python3.13/site-packages/django/views/debug.py", line 428, in get_traceback_html
    c = Context(self.get_traceback_data(), use_l10n=False)
                ~~~~~~~~~~~~~~~~~~~~~~~^^
  File "/home/markmur88/envAPP/lib/python3.13/site-packages/django/views/debug.py", line 411, in get_traceback_data
    c["raising_view_name"] = get_caller(self.request)
                             ~~~~~~~~~~^^^^^^^^^^^^^^
  File "/home/markmur88/envAPP/lib/python3.13/site-packages/django/views/debug.py", line 102, in get_caller
    resolver_match = resolve(request.path)
  File "/home/markmur88/envAPP/lib/python3.13/site-packages/django/urls/base.py", line 25, in resolve
    return get_resolver(urlconf).resolve(path)
           ~~~~~~~~~~~~~~~~~~~~~~~~~~~~~^^^^^^
  File "/home/markmur88/envAPP/lib/python3.13/site-packages/django/urls/resolvers.py", line 666, in resolve
    for pattern in self.url_patterns:
                   ^^^^^^^^^^^^^^^^^
  File "/home/markmur88/envAPP/lib/python3.13/site-packages/django/utils/functional.py", line 47, in __get__
    res = instance.__dict__[self.name] = self.func(instance)
                                         ~~~~~~~~~^^^^^^^^^^
  File "/home/markmur88/envAPP/lib/python3.13/site-packages/django/urls/resolvers.py", line 718, in url_patterns
    patterns = getattr(self.urlconf_module, "urlpatterns", self.urlconf_module)
                       ^^^^^^^^^^^^^^^^^^^
  File "/home/markmur88/envAPP/lib/python3.13/site-packages/django/utils/functional.py", line 47, in __get__
    res = instance.__dict__[self.name] = self.func(instance)
                                         ~~~~~~~~~^^^^^^^^^^
  File "/home/markmur88/envAPP/lib/python3.13/site-packages/django/urls/resolvers.py", line 711, in urlconf_module
    return import_module(self.urlconf_name)
  File "/usr/lib/python3.13/importlib/__init__.py", line 88, in import_module
    return _bootstrap._gcd_import(name[level:], package, level)
           ~~~~~~~~~~~~~~~~~~~~~~^^^^^^^^^^^^^^^^^^^^^^^^^^^^^^
  File "<frozen importlib._bootstrap>", line 1387, in _gcd_import
  File "<frozen importlib._bootstrap>", line 1360, in _find_and_load
  File "<frozen importlib._bootstrap>", line 1331, in _find_and_load_unlocked
  File "<frozen importlib._bootstrap>", line 935, in _load_unlocked
  File "<frozen importlib._bootstrap_external>", line 1026, in exec_module
  File "<frozen importlib._bootstrap>", line 488, in _call_with_frames_removed
  File "/home/markmur88/api_bank_h2/config/urls.py", line 26, in <module>
    from api.gpt4.views import oauth2_authorize, oauth2_callback
  File "/home/markmur88/api_bank_h2/api/gpt4/views.py", line 1319, in <module>
    from .conexion_banco_refactor import (
    ...<3 lines>...
    )
  File "/home/markmur88/api_bank_h2/api/gpt4/conexion_banco_refactor.py", line 203, in <module>
    connector = BankConnector(config=config, logger=logger)
  File "/home/markmur88/api_bank_h2/api/gpt4/conexion_banco_refactor.py", line 102, in __init__
    self._init_client()
    ~~~~~~~~~~~~~~~~~^^
  File "/home/markmur88/api_bank_h2/api/gpt4/conexion_banco_refactor.py", line 110, in _init_client
    dns_bank_raw = self.config.get('DNS_BANCO', required=True)
  File "/home/markmur88/api_bank_h2/api/gpt4/conexion_banco_refactor.py", line 34, in get
    raise ConfigError(f"Missing required config: {name}")
api.gpt4.conexion_banco_refactor.ConfigError: Missing required config: BANK_DNS_BANCO

During handling of the above exception, another exception occurred:

Traceback (most recent call last):
  File "/home/markmur88/envAPP/lib/python3.13/site-packages/gunicorn/workers/sync.py", line 134, in handle
    self.handle_request(listener, req, client, addr)
    ~~~~~~~~~~~~~~~~~~~^^^^^^^^^^^^^^^^^^^^^^^^^^^^^
  File "/home/markmur88/envAPP/lib/python3.13/site-packages/gunicorn/workers/sync.py", line 177, in handle_request
    respiter = self.wsgi(environ, resp.start_response)
  File "/home/markmur88/envAPP/lib/python3.13/site-packages/django/core/handlers/wsgi.py", line 124, in __call__
    response = self.get_response(request)
  File "/home/markmur88/envAPP/lib/python3.13/site-packages/django/core/handlers/base.py", line 140, in get_response
    response = self._middleware_chain(request)
  File "/home/markmur88/envAPP/lib/python3.13/site-packages/django/core/handlers/exception.py", line 57, in inner
    response = response_for_exception(request, exc)
  File "/home/markmur88/envAPP/lib/python3.13/site-packages/django/core/handlers/exception.py", line 140, in response_for_exception
    response = handle_uncaught_exception(
        request, get_resolver(get_urlconf()), sys.exc_info()
    )
  File "/home/markmur88/envAPP/lib/python3.13/site-packages/django/core/handlers/exception.py", line 181, in handle_uncaught_exception
    return debug.technical_500_response(request, *exc_info)
           ~~~~~~~~~~~~~~~~~~~~~~~~~~~~^^^^^^^^^^^^^^^^^^^^
  File "/home/markmur88/envAPP/lib/python3.13/site-packages/django/views/debug.py", line 69, in technical_500_response
    html = reporter.get_traceback_html()
  File "/home/markmur88/envAPP/lib/python3.13/site-packages/django/views/debug.py", line 428, in get_traceback_html
    c = Context(self.get_traceback_data(), use_l10n=False)
                ~~~~~~~~~~~~~~~~~~~~~~~^^
  File "/home/markmur88/envAPP/lib/python3.13/site-packages/django/views/debug.py", line 411, in get_traceback_data
    c["raising_view_name"] = get_caller(self.request)
                             ~~~~~~~~~~^^^^^^^^^^^^^^
  File "/home/markmur88/envAPP/lib/python3.13/site-packages/django/views/debug.py", line 102, in get_caller
    resolver_match = resolve(request.path)
  File "/home/markmur88/envAPP/lib/python3.13/site-packages/django/urls/base.py", line 25, in resolve
    return get_resolver(urlconf).resolve(path)
           ~~~~~~~~~~~~~~~~~~~~~~~~~~~~~^^^^^^
  File "/home/markmur88/envAPP/lib/python3.13/site-packages/django/urls/resolvers.py", line 666, in resolve
    for pattern in self.url_patterns:
                   ^^^^^^^^^^^^^^^^^
  File "/home/markmur88/envAPP/lib/python3.13/site-packages/django/utils/functional.py", line 47, in __get__
    res = instance.__dict__[self.name] = self.func(instance)
                                         ~~~~~~~~~^^^^^^^^^^
  File "/home/markmur88/envAPP/lib/python3.13/site-packages/django/urls/resolvers.py", line 718, in url_patterns
    patterns = getattr(self.urlconf_module, "urlpatterns", self.urlconf_module)
                       ^^^^^^^^^^^^^^^^^^^
  File "/home/markmur88/envAPP/lib/python3.13/site-packages/django/utils/functional.py", line 47, in __get__
    res = instance.__dict__[self.name] = self.func(instance)
                                         ~~~~~~~~~^^^^^^^^^^
  File "/home/markmur88/envAPP/lib/python3.13/site-packages/django/urls/resolvers.py", line 711, in urlconf_module
    return import_module(self.urlconf_name)
  File "/usr/lib/python3.13/importlib/__init__.py", line 88, in import_module
    return _bootstrap._gcd_import(name[level:], package, level)
           ~~~~~~~~~~~~~~~~~~~~~~^^^^^^^^^^^^^^^^^^^^^^^^^^^^^^
  File "<frozen importlib._bootstrap>", line 1387, in _gcd_import
  File "<frozen importlib._bootstrap>", line 1360, in _find_and_load
  File "<frozen importlib._bootstrap>", line 1331, in _find_and_load_unlocked
  File "<frozen importlib._bootstrap>", line 935, in _load_unlocked
  File "<frozen importlib._bootstrap_external>", line 1026, in exec_module
  File "<frozen importlib._bootstrap>", line 488, in _call_with_frames_removed
  File "/home/markmur88/api_bank_h2/config/urls.py", line 26, in <module>
    from api.gpt4.views import oauth2_authorize, oauth2_callback
  File "/home/markmur88/api_bank_h2/api/gpt4/views.py", line 1319, in <module>
    from .conexion_banco_refactor import (
    ...<3 lines>...
    )
  File "/home/markmur88/api_bank_h2/api/gpt4/conexion_banco_refactor.py", line 203, in <module>
    connector = BankConnector(config=config, logger=logger)
  File "/home/markmur88/api_bank_h2/api/gpt4/conexion_banco_refactor.py", line 102, in __init__
    self._init_client()
    ~~~~~~~~~~~~~~~~~^^
  File "/home/markmur88/api_bank_h2/api/gpt4/conexion_banco_refactor.py", line 110, in _init_client
    dns_bank_raw = self.config.get('DNS_BANCO', required=True)
  File "/home/markmur88/api_bank_h2/api/gpt4/conexion_banco_refactor.py", line 34, in get
    raise ConfigError(f"Missing required config: {name}")
api.gpt4.conexion_banco_refactor.ConfigError: Missing required config: BANK_DNS_BANCO
[2025-06-17 23:56:56 +0200] [317609] [ERROR] Error handling request /
Traceback (most recent call last):
  File "/home/markmur88/envAPP/lib/python3.13/site-packages/django/core/handlers/exception.py", line 55, in inner
    response = get_response(request)
  File "/home/markmur88/envAPP/lib/python3.13/site-packages/debug_toolbar/middleware.py", line 114, in __call__
    if not show_toolbar(request) or DebugToolbar.is_toolbar_request(request):
                                    ~~~~~~~~~~~~~~~~~~~~~~~~~~~~~~~^^^^^^^^^
  File "/home/markmur88/envAPP/lib/python3.13/site-packages/debug_toolbar/toolbar.py", line 185, in is_toolbar_request
    resolver_match = request.resolver_match or resolve(
                                               ~~~~~~~^
        request.path_info, getattr(request, "urlconf", None)
        ^^^^^^^^^^^^^^^^^^^^^^^^^^^^^^^^^^^^^^^^^^^^^^^^^^^^
    )
    ^
  File "/home/markmur88/envAPP/lib/python3.13/site-packages/django/urls/base.py", line 25, in resolve
    return get_resolver(urlconf).resolve(path)
           ~~~~~~~~~~~~~~~~~~~~~~~~~~~~~^^^^^^
  File "/home/markmur88/envAPP/lib/python3.13/site-packages/django/urls/resolvers.py", line 666, in resolve
    for pattern in self.url_patterns:
                   ^^^^^^^^^^^^^^^^^
  File "/home/markmur88/envAPP/lib/python3.13/site-packages/django/utils/functional.py", line 47, in __get__
    res = instance.__dict__[self.name] = self.func(instance)
                                         ~~~~~~~~~^^^^^^^^^^
  File "/home/markmur88/envAPP/lib/python3.13/site-packages/django/urls/resolvers.py", line 718, in url_patterns
    patterns = getattr(self.urlconf_module, "urlpatterns", self.urlconf_module)
                       ^^^^^^^^^^^^^^^^^^^
  File "/home/markmur88/envAPP/lib/python3.13/site-packages/django/utils/functional.py", line 47, in __get__
    res = instance.__dict__[self.name] = self.func(instance)
                                         ~~~~~~~~~^^^^^^^^^^
  File "/home/markmur88/envAPP/lib/python3.13/site-packages/django/urls/resolvers.py", line 711, in urlconf_module
    return import_module(self.urlconf_name)
  File "/usr/lib/python3.13/importlib/__init__.py", line 88, in import_module
    return _bootstrap._gcd_import(name[level:], package, level)
           ~~~~~~~~~~~~~~~~~~~~~~^^^^^^^^^^^^^^^^^^^^^^^^^^^^^^
  File "<frozen importlib._bootstrap>", line 1387, in _gcd_import
  File "<frozen importlib._bootstrap>", line 1360, in _find_and_load
  File "<frozen importlib._bootstrap>", line 1331, in _find_and_load_unlocked
  File "<frozen importlib._bootstrap>", line 935, in _load_unlocked
  File "<frozen importlib._bootstrap_external>", line 1026, in exec_module
  File "<frozen importlib._bootstrap>", line 488, in _call_with_frames_removed
  File "/home/markmur88/api_bank_h2/config/urls.py", line 26, in <module>
    from api.gpt4.views import oauth2_authorize, oauth2_callback
  File "/home/markmur88/api_bank_h2/api/gpt4/views.py", line 1319, in <module>
    from .conexion_banco_refactor import (
    ...<3 lines>...
    )
  File "/home/markmur88/api_bank_h2/api/gpt4/conexion_banco_refactor.py", line 203, in <module>
    connector = BankConnector(config=config, logger=logger)
  File "/home/markmur88/api_bank_h2/api/gpt4/conexion_banco_refactor.py", line 102, in __init__
    self._init_client()
    ~~~~~~~~~~~~~~~~~^^
  File "/home/markmur88/api_bank_h2/api/gpt4/conexion_banco_refactor.py", line 110, in _init_client
    dns_bank_raw = self.config.get('DNS_BANCO', required=True)
  File "/home/markmur88/api_bank_h2/api/gpt4/conexion_banco_refactor.py", line 34, in get
    raise ConfigError(f"Missing required config: {name}")
api.gpt4.conexion_banco_refactor.ConfigError: Missing required config: BANK_DNS_BANCO

During handling of the above exception, another exception occurred:

Traceback (most recent call last):
  File "/home/markmur88/envAPP/lib/python3.13/site-packages/django/core/handlers/exception.py", line 55, in inner
    response = get_response(request)
  File "/home/markmur88/envAPP/lib/python3.13/site-packages/django/utils/deprecation.py", line 120, in __call__
    response = response or self.get_response(request)
                           ~~~~~~~~~~~~~~~~~^^^^^^^^^
  File "/home/markmur88/envAPP/lib/python3.13/site-packages/django/core/handlers/exception.py", line 57, in inner
    response = response_for_exception(request, exc)
  File "/home/markmur88/envAPP/lib/python3.13/site-packages/django/core/handlers/exception.py", line 140, in response_for_exception
    response = handle_uncaught_exception(
        request, get_resolver(get_urlconf()), sys.exc_info()
    )
  File "/home/markmur88/envAPP/lib/python3.13/site-packages/django/core/handlers/exception.py", line 181, in handle_uncaught_exception
    return debug.technical_500_response(request, *exc_info)
           ~~~~~~~~~~~~~~~~~~~~~~~~~~~~^^^^^^^^^^^^^^^^^^^^
  File "/home/markmur88/envAPP/lib/python3.13/site-packages/django/views/debug.py", line 69, in technical_500_response
    html = reporter.get_traceback_html()
  File "/home/markmur88/envAPP/lib/python3.13/site-packages/django/views/debug.py", line 428, in get_traceback_html
    c = Context(self.get_traceback_data(), use_l10n=False)
                ~~~~~~~~~~~~~~~~~~~~~~~^^
  File "/home/markmur88/envAPP/lib/python3.13/site-packages/django/views/debug.py", line 411, in get_traceback_data
    c["raising_view_name"] = get_caller(self.request)
                             ~~~~~~~~~~^^^^^^^^^^^^^^
  File "/home/markmur88/envAPP/lib/python3.13/site-packages/django/views/debug.py", line 102, in get_caller
    resolver_match = resolve(request.path)
  File "/home/markmur88/envAPP/lib/python3.13/site-packages/django/urls/base.py", line 25, in resolve
    return get_resolver(urlconf).resolve(path)
           ~~~~~~~~~~~~~~~~~~~~~~~~~~~~~^^^^^^
  File "/home/markmur88/envAPP/lib/python3.13/site-packages/django/urls/resolvers.py", line 666, in resolve
    for pattern in self.url_patterns:
                   ^^^^^^^^^^^^^^^^^
  File "/home/markmur88/envAPP/lib/python3.13/site-packages/django/utils/functional.py", line 47, in __get__
    res = instance.__dict__[self.name] = self.func(instance)
                                         ~~~~~~~~~^^^^^^^^^^
  File "/home/markmur88/envAPP/lib/python3.13/site-packages/django/urls/resolvers.py", line 718, in url_patterns
    patterns = getattr(self.urlconf_module, "urlpatterns", self.urlconf_module)
                       ^^^^^^^^^^^^^^^^^^^
  File "/home/markmur88/envAPP/lib/python3.13/site-packages/django/utils/functional.py", line 47, in __get__
    res = instance.__dict__[self.name] = self.func(instance)
                                         ~~~~~~~~~^^^^^^^^^^
  File "/home/markmur88/envAPP/lib/python3.13/site-packages/django/urls/resolvers.py", line 711, in urlconf_module
    return import_module(self.urlconf_name)
  File "/usr/lib/python3.13/importlib/__init__.py", line 88, in import_module
    return _bootstrap._gcd_import(name[level:], package, level)
           ~~~~~~~~~~~~~~~~~~~~~~^^^^^^^^^^^^^^^^^^^^^^^^^^^^^^
  File "<frozen importlib._bootstrap>", line 1387, in _gcd_import
  File "<frozen importlib._bootstrap>", line 1360, in _find_and_load
  File "<frozen importlib._bootstrap>", line 1331, in _find_and_load_unlocked
  File "<frozen importlib._bootstrap>", line 935, in _load_unlocked
  File "<frozen importlib._bootstrap_external>", line 1026, in exec_module
  File "<frozen importlib._bootstrap>", line 488, in _call_with_frames_removed
  File "/home/markmur88/api_bank_h2/config/urls.py", line 26, in <module>
    from api.gpt4.views import oauth2_authorize, oauth2_callback
  File "/home/markmur88/api_bank_h2/api/gpt4/views.py", line 1319, in <module>
    from .conexion_banco_refactor import (
    ...<3 lines>...
    )
  File "/home/markmur88/api_bank_h2/api/gpt4/conexion_banco_refactor.py", line 203, in <module>
    connector = BankConnector(config=config, logger=logger)
  File "/home/markmur88/api_bank_h2/api/gpt4/conexion_banco_refactor.py", line 102, in __init__
    self._init_client()
    ~~~~~~~~~~~~~~~~~^^
  File "/home/markmur88/api_bank_h2/api/gpt4/conexion_banco_refactor.py", line 110, in _init_client
    dns_bank_raw = self.config.get('DNS_BANCO', required=True)
  File "/home/markmur88/api_bank_h2/api/gpt4/conexion_banco_refactor.py", line 34, in get
    raise ConfigError(f"Missing required config: {name}")
api.gpt4.conexion_banco_refactor.ConfigError: Missing required config: BANK_DNS_BANCO

During handling of the above exception, another exception occurred:

Traceback (most recent call last):
  File "/home/markmur88/envAPP/lib/python3.13/site-packages/django/core/handlers/exception.py", line 55, in inner
    response = get_response(request)
  File "/home/markmur88/envAPP/lib/python3.13/site-packages/whitenoise/middleware.py", line 123, in __call__
    return self.get_response(request)
           ~~~~~~~~~~~~~~~~~^^^^^^^^^
  File "/home/markmur88/envAPP/lib/python3.13/site-packages/django/core/handlers/exception.py", line 57, in inner
    response = response_for_exception(request, exc)
  File "/home/markmur88/envAPP/lib/python3.13/site-packages/django/core/handlers/exception.py", line 140, in response_for_exception
    response = handle_uncaught_exception(
        request, get_resolver(get_urlconf()), sys.exc_info()
    )
  File "/home/markmur88/envAPP/lib/python3.13/site-packages/django/core/handlers/exception.py", line 181, in handle_uncaught_exception
    return debug.technical_500_response(request, *exc_info)
           ~~~~~~~~~~~~~~~~~~~~~~~~~~~~^^^^^^^^^^^^^^^^^^^^
  File "/home/markmur88/envAPP/lib/python3.13/site-packages/django/views/debug.py", line 69, in technical_500_response
    html = reporter.get_traceback_html()
  File "/home/markmur88/envAPP/lib/python3.13/site-packages/django/views/debug.py", line 428, in get_traceback_html
    c = Context(self.get_traceback_data(), use_l10n=False)
                ~~~~~~~~~~~~~~~~~~~~~~~^^
  File "/home/markmur88/envAPP/lib/python3.13/site-packages/django/views/debug.py", line 411, in get_traceback_data
    c["raising_view_name"] = get_caller(self.request)
                             ~~~~~~~~~~^^^^^^^^^^^^^^
  File "/home/markmur88/envAPP/lib/python3.13/site-packages/django/views/debug.py", line 102, in get_caller
    resolver_match = resolve(request.path)
  File "/home/markmur88/envAPP/lib/python3.13/site-packages/django/urls/base.py", line 25, in resolve
    return get_resolver(urlconf).resolve(path)
           ~~~~~~~~~~~~~~~~~~~~~~~~~~~~~^^^^^^
  File "/home/markmur88/envAPP/lib/python3.13/site-packages/django/urls/resolvers.py", line 666, in resolve
    for pattern in self.url_patterns:
                   ^^^^^^^^^^^^^^^^^
  File "/home/markmur88/envAPP/lib/python3.13/site-packages/django/utils/functional.py", line 47, in __get__
    res = instance.__dict__[self.name] = self.func(instance)
                                         ~~~~~~~~~^^^^^^^^^^
  File "/home/markmur88/envAPP/lib/python3.13/site-packages/django/urls/resolvers.py", line 718, in url_patterns
    patterns = getattr(self.urlconf_module, "urlpatterns", self.urlconf_module)
                       ^^^^^^^^^^^^^^^^^^^
  File "/home/markmur88/envAPP/lib/python3.13/site-packages/django/utils/functional.py", line 47, in __get__
    res = instance.__dict__[self.name] = self.func(instance)
                                         ~~~~~~~~~^^^^^^^^^^
  File "/home/markmur88/envAPP/lib/python3.13/site-packages/django/urls/resolvers.py", line 711, in urlconf_module
    return import_module(self.urlconf_name)
  File "/usr/lib/python3.13/importlib/__init__.py", line 88, in import_module
    return _bootstrap._gcd_import(name[level:], package, level)
           ~~~~~~~~~~~~~~~~~~~~~~^^^^^^^^^^^^^^^^^^^^^^^^^^^^^^
  File "<frozen importlib._bootstrap>", line 1387, in _gcd_import
  File "<frozen importlib._bootstrap>", line 1360, in _find_and_load
  File "<frozen importlib._bootstrap>", line 1331, in _find_and_load_unlocked
  File "<frozen importlib._bootstrap>", line 935, in _load_unlocked
  File "<frozen importlib._bootstrap_external>", line 1026, in exec_module
  File "<frozen importlib._bootstrap>", line 488, in _call_with_frames_removed
  File "/home/markmur88/api_bank_h2/config/urls.py", line 26, in <module>
    from api.gpt4.views import oauth2_authorize, oauth2_callback
  File "/home/markmur88/api_bank_h2/api/gpt4/views.py", line 1319, in <module>
    from .conexion_banco_refactor import (
    ...<3 lines>...
    )
  File "/home/markmur88/api_bank_h2/api/gpt4/conexion_banco_refactor.py", line 203, in <module>
    connector = BankConnector(config=config, logger=logger)
  File "/home/markmur88/api_bank_h2/api/gpt4/conexion_banco_refactor.py", line 102, in __init__
    self._init_client()
    ~~~~~~~~~~~~~~~~~^^
  File "/home/markmur88/api_bank_h2/api/gpt4/conexion_banco_refactor.py", line 110, in _init_client
    dns_bank_raw = self.config.get('DNS_BANCO', required=True)
  File "/home/markmur88/api_bank_h2/api/gpt4/conexion_banco_refactor.py", line 34, in get
    raise ConfigError(f"Missing required config: {name}")
api.gpt4.conexion_banco_refactor.ConfigError: Missing required config: BANK_DNS_BANCO

During handling of the above exception, another exception occurred:

Traceback (most recent call last):
  File "/home/markmur88/envAPP/lib/python3.13/site-packages/gunicorn/workers/sync.py", line 134, in handle
    self.handle_request(listener, req, client, addr)
    ~~~~~~~~~~~~~~~~~~~^^^^^^^^^^^^^^^^^^^^^^^^^^^^^
  File "/home/markmur88/envAPP/lib/python3.13/site-packages/gunicorn/workers/sync.py", line 177, in handle_request
    respiter = self.wsgi(environ, resp.start_response)
  File "/home/markmur88/envAPP/lib/python3.13/site-packages/django/core/handlers/wsgi.py", line 124, in __call__
    response = self.get_response(request)
  File "/home/markmur88/envAPP/lib/python3.13/site-packages/django/core/handlers/base.py", line 140, in get_response
    response = self._middleware_chain(request)
  File "/home/markmur88/envAPP/lib/python3.13/site-packages/django/core/handlers/exception.py", line 57, in inner
    response = response_for_exception(request, exc)
  File "/home/markmur88/envAPP/lib/python3.13/site-packages/django/core/handlers/exception.py", line 140, in response_for_exception
    response = handle_uncaught_exception(
        request, get_resolver(get_urlconf()), sys.exc_info()
    )
  File "/home/markmur88/envAPP/lib/python3.13/site-packages/django/core/handlers/exception.py", line 181, in handle_uncaught_exception
    return debug.technical_500_response(request, *exc_info)
           ~~~~~~~~~~~~~~~~~~~~~~~~~~~~^^^^^^^^^^^^^^^^^^^^
  File "/home/markmur88/envAPP/lib/python3.13/site-packages/django/views/debug.py", line 69, in technical_500_response
    html = reporter.get_traceback_html()
  File "/home/markmur88/envAPP/lib/python3.13/site-packages/django/views/debug.py", line 428, in get_traceback_html
    c = Context(self.get_traceback_data(), use_l10n=False)
                ~~~~~~~~~~~~~~~~~~~~~~~^^
  File "/home/markmur88/envAPP/lib/python3.13/site-packages/django/views/debug.py", line 411, in get_traceback_data
    c["raising_view_name"] = get_caller(self.request)
                             ~~~~~~~~~~^^^^^^^^^^^^^^
  File "/home/markmur88/envAPP/lib/python3.13/site-packages/django/views/debug.py", line 102, in get_caller
    resolver_match = resolve(request.path)
  File "/home/markmur88/envAPP/lib/python3.13/site-packages/django/urls/base.py", line 25, in resolve
    return get_resolver(urlconf).resolve(path)
           ~~~~~~~~~~~~~~~~~~~~~~~~~~~~~^^^^^^
  File "/home/markmur88/envAPP/lib/python3.13/site-packages/django/urls/resolvers.py", line 666, in resolve
    for pattern in self.url_patterns:
                   ^^^^^^^^^^^^^^^^^
  File "/home/markmur88/envAPP/lib/python3.13/site-packages/django/utils/functional.py", line 47, in __get__
    res = instance.__dict__[self.name] = self.func(instance)
                                         ~~~~~~~~~^^^^^^^^^^
  File "/home/markmur88/envAPP/lib/python3.13/site-packages/django/urls/resolvers.py", line 718, in url_patterns
    patterns = getattr(self.urlconf_module, "urlpatterns", self.urlconf_module)
                       ^^^^^^^^^^^^^^^^^^^
  File "/home/markmur88/envAPP/lib/python3.13/site-packages/django/utils/functional.py", line 47, in __get__
    res = instance.__dict__[self.name] = self.func(instance)
                                         ~~~~~~~~~^^^^^^^^^^
  File "/home/markmur88/envAPP/lib/python3.13/site-packages/django/urls/resolvers.py", line 711, in urlconf_module
    return import_module(self.urlconf_name)
  File "/usr/lib/python3.13/importlib/__init__.py", line 88, in import_module
    return _bootstrap._gcd_import(name[level:], package, level)
           ~~~~~~~~~~~~~~~~~~~~~~^^^^^^^^^^^^^^^^^^^^^^^^^^^^^^
  File "<frozen importlib._bootstrap>", line 1387, in _gcd_import
  File "<frozen importlib._bootstrap>", line 1360, in _find_and_load
  File "<frozen importlib._bootstrap>", line 1331, in _find_and_load_unlocked
  File "<frozen importlib._bootstrap>", line 935, in _load_unlocked
  File "<frozen importlib._bootstrap_external>", line 1026, in exec_module
  File "<frozen importlib._bootstrap>", line 488, in _call_with_frames_removed
  File "/home/markmur88/api_bank_h2/config/urls.py", line 26, in <module>
    from api.gpt4.views import oauth2_authorize, oauth2_callback
  File "/home/markmur88/api_bank_h2/api/gpt4/views.py", line 1319, in <module>
    from .conexion_banco_refactor import (
    ...<3 lines>...
    )
  File "/home/markmur88/api_bank_h2/api/gpt4/conexion_banco_refactor.py", line 203, in <module>
    connector = BankConnector(config=config, logger=logger)
  File "/home/markmur88/api_bank_h2/api/gpt4/conexion_banco_refactor.py", line 102, in __init__
    self._init_client()
    ~~~~~~~~~~~~~~~~~^^
  File "/home/markmur88/api_bank_h2/api/gpt4/conexion_banco_refactor.py", line 110, in _init_client
    dns_bank_raw = self.config.get('DNS_BANCO', required=True)
  File "/home/markmur88/api_bank_h2/api/gpt4/conexion_banco_refactor.py", line 34, in get
    raise ConfigError(f"Missing required config: {name}")
api.gpt4.conexion_banco_refactor.ConfigError: Missing required config: BANK_DNS_BANCO
[2025-06-17 23:57:41 +0200] [317609] [ERROR] Error handling request /
Traceback (most recent call last):
  File "/home/markmur88/envAPP/lib/python3.13/site-packages/django/core/handlers/exception.py", line 55, in inner
    response = get_response(request)
  File "/home/markmur88/envAPP/lib/python3.13/site-packages/debug_toolbar/middleware.py", line 114, in __call__
    if not show_toolbar(request) or DebugToolbar.is_toolbar_request(request):
                                    ~~~~~~~~~~~~~~~~~~~~~~~~~~~~~~~^^^^^^^^^
  File "/home/markmur88/envAPP/lib/python3.13/site-packages/debug_toolbar/toolbar.py", line 185, in is_toolbar_request
    resolver_match = request.resolver_match or resolve(
                                               ~~~~~~~^
        request.path_info, getattr(request, "urlconf", None)
        ^^^^^^^^^^^^^^^^^^^^^^^^^^^^^^^^^^^^^^^^^^^^^^^^^^^^
    )
    ^
  File "/home/markmur88/envAPP/lib/python3.13/site-packages/django/urls/base.py", line 25, in resolve
    return get_resolver(urlconf).resolve(path)
           ~~~~~~~~~~~~~~~~~~~~~~~~~~~~~^^^^^^
  File "/home/markmur88/envAPP/lib/python3.13/site-packages/django/urls/resolvers.py", line 666, in resolve
    for pattern in self.url_patterns:
                   ^^^^^^^^^^^^^^^^^
  File "/home/markmur88/envAPP/lib/python3.13/site-packages/django/utils/functional.py", line 47, in __get__
    res = instance.__dict__[self.name] = self.func(instance)
                                         ~~~~~~~~~^^^^^^^^^^
  File "/home/markmur88/envAPP/lib/python3.13/site-packages/django/urls/resolvers.py", line 718, in url_patterns
    patterns = getattr(self.urlconf_module, "urlpatterns", self.urlconf_module)
                       ^^^^^^^^^^^^^^^^^^^
  File "/home/markmur88/envAPP/lib/python3.13/site-packages/django/utils/functional.py", line 47, in __get__
    res = instance.__dict__[self.name] = self.func(instance)
                                         ~~~~~~~~~^^^^^^^^^^
  File "/home/markmur88/envAPP/lib/python3.13/site-packages/django/urls/resolvers.py", line 711, in urlconf_module
    return import_module(self.urlconf_name)
  File "/usr/lib/python3.13/importlib/__init__.py", line 88, in import_module
    return _bootstrap._gcd_import(name[level:], package, level)
           ~~~~~~~~~~~~~~~~~~~~~~^^^^^^^^^^^^^^^^^^^^^^^^^^^^^^
  File "<frozen importlib._bootstrap>", line 1387, in _gcd_import
  File "<frozen importlib._bootstrap>", line 1360, in _find_and_load
  File "<frozen importlib._bootstrap>", line 1331, in _find_and_load_unlocked
  File "<frozen importlib._bootstrap>", line 935, in _load_unlocked
  File "<frozen importlib._bootstrap_external>", line 1026, in exec_module
  File "<frozen importlib._bootstrap>", line 488, in _call_with_frames_removed
  File "/home/markmur88/api_bank_h2/config/urls.py", line 26, in <module>
    from api.gpt4.views import oauth2_authorize, oauth2_callback
  File "/home/markmur88/api_bank_h2/api/gpt4/views.py", line 1319, in <module>
    from .conexion_banco_refactor import (
    ...<3 lines>...
    )
  File "/home/markmur88/api_bank_h2/api/gpt4/conexion_banco_refactor.py", line 203, in <module>
    connector = BankConnector(config=config, logger=logger)
  File "/home/markmur88/api_bank_h2/api/gpt4/conexion_banco_refactor.py", line 102, in __init__
    self._init_client()
    ~~~~~~~~~~~~~~~~~^^
  File "/home/markmur88/api_bank_h2/api/gpt4/conexion_banco_refactor.py", line 110, in _init_client
    dns_bank_raw = self.config.get('DNS_BANCO', required=True)
  File "/home/markmur88/api_bank_h2/api/gpt4/conexion_banco_refactor.py", line 34, in get
    raise ConfigError(f"Missing required config: {name}")
api.gpt4.conexion_banco_refactor.ConfigError: Missing required config: BANK_DNS_BANCO

During handling of the above exception, another exception occurred:

Traceback (most recent call last):
  File "/home/markmur88/envAPP/lib/python3.13/site-packages/django/core/handlers/exception.py", line 55, in inner
    response = get_response(request)
  File "/home/markmur88/envAPP/lib/python3.13/site-packages/django/utils/deprecation.py", line 120, in __call__
    response = response or self.get_response(request)
                           ~~~~~~~~~~~~~~~~~^^^^^^^^^
  File "/home/markmur88/envAPP/lib/python3.13/site-packages/django/core/handlers/exception.py", line 57, in inner
    response = response_for_exception(request, exc)
  File "/home/markmur88/envAPP/lib/python3.13/site-packages/django/core/handlers/exception.py", line 140, in response_for_exception
    response = handle_uncaught_exception(
        request, get_resolver(get_urlconf()), sys.exc_info()
    )
  File "/home/markmur88/envAPP/lib/python3.13/site-packages/django/core/handlers/exception.py", line 181, in handle_uncaught_exception
    return debug.technical_500_response(request, *exc_info)
           ~~~~~~~~~~~~~~~~~~~~~~~~~~~~^^^^^^^^^^^^^^^^^^^^
  File "/home/markmur88/envAPP/lib/python3.13/site-packages/django/views/debug.py", line 69, in technical_500_response
    html = reporter.get_traceback_html()
  File "/home/markmur88/envAPP/lib/python3.13/site-packages/django/views/debug.py", line 428, in get_traceback_html
    c = Context(self.get_traceback_data(), use_l10n=False)
                ~~~~~~~~~~~~~~~~~~~~~~~^^
  File "/home/markmur88/envAPP/lib/python3.13/site-packages/django/views/debug.py", line 411, in get_traceback_data
    c["raising_view_name"] = get_caller(self.request)
                             ~~~~~~~~~~^^^^^^^^^^^^^^
  File "/home/markmur88/envAPP/lib/python3.13/site-packages/django/views/debug.py", line 102, in get_caller
    resolver_match = resolve(request.path)
  File "/home/markmur88/envAPP/lib/python3.13/site-packages/django/urls/base.py", line 25, in resolve
    return get_resolver(urlconf).resolve(path)
           ~~~~~~~~~~~~~~~~~~~~~~~~~~~~~^^^^^^
  File "/home/markmur88/envAPP/lib/python3.13/site-packages/django/urls/resolvers.py", line 666, in resolve
    for pattern in self.url_patterns:
                   ^^^^^^^^^^^^^^^^^
  File "/home/markmur88/envAPP/lib/python3.13/site-packages/django/utils/functional.py", line 47, in __get__
    res = instance.__dict__[self.name] = self.func(instance)
                                         ~~~~~~~~~^^^^^^^^^^
  File "/home/markmur88/envAPP/lib/python3.13/site-packages/django/urls/resolvers.py", line 718, in url_patterns
    patterns = getattr(self.urlconf_module, "urlpatterns", self.urlconf_module)
                       ^^^^^^^^^^^^^^^^^^^
  File "/home/markmur88/envAPP/lib/python3.13/site-packages/django/utils/functional.py", line 47, in __get__
    res = instance.__dict__[self.name] = self.func(instance)
                                         ~~~~~~~~~^^^^^^^^^^
  File "/home/markmur88/envAPP/lib/python3.13/site-packages/django/urls/resolvers.py", line 711, in urlconf_module
    return import_module(self.urlconf_name)
  File "/usr/lib/python3.13/importlib/__init__.py", line 88, in import_module
    return _bootstrap._gcd_import(name[level:], package, level)
           ~~~~~~~~~~~~~~~~~~~~~~^^^^^^^^^^^^^^^^^^^^^^^^^^^^^^
  File "<frozen importlib._bootstrap>", line 1387, in _gcd_import
  File "<frozen importlib._bootstrap>", line 1360, in _find_and_load
  File "<frozen importlib._bootstrap>", line 1331, in _find_and_load_unlocked
  File "<frozen importlib._bootstrap>", line 935, in _load_unlocked
  File "<frozen importlib._bootstrap_external>", line 1026, in exec_module
  File "<frozen importlib._bootstrap>", line 488, in _call_with_frames_removed
  File "/home/markmur88/api_bank_h2/config/urls.py", line 26, in <module>
    from api.gpt4.views import oauth2_authorize, oauth2_callback
  File "/home/markmur88/api_bank_h2/api/gpt4/views.py", line 1319, in <module>
    from .conexion_banco_refactor import (
    ...<3 lines>...
    )
  File "/home/markmur88/api_bank_h2/api/gpt4/conexion_banco_refactor.py", line 203, in <module>
    connector = BankConnector(config=config, logger=logger)
  File "/home/markmur88/api_bank_h2/api/gpt4/conexion_banco_refactor.py", line 102, in __init__
    self._init_client()
    ~~~~~~~~~~~~~~~~~^^
  File "/home/markmur88/api_bank_h2/api/gpt4/conexion_banco_refactor.py", line 110, in _init_client
    dns_bank_raw = self.config.get('DNS_BANCO', required=True)
  File "/home/markmur88/api_bank_h2/api/gpt4/conexion_banco_refactor.py", line 34, in get
    raise ConfigError(f"Missing required config: {name}")
api.gpt4.conexion_banco_refactor.ConfigError: Missing required config: BANK_DNS_BANCO

During handling of the above exception, another exception occurred:

Traceback (most recent call last):
  File "/home/markmur88/envAPP/lib/python3.13/site-packages/django/core/handlers/exception.py", line 55, in inner
    response = get_response(request)
  File "/home/markmur88/envAPP/lib/python3.13/site-packages/whitenoise/middleware.py", line 123, in __call__
    return self.get_response(request)
           ~~~~~~~~~~~~~~~~~^^^^^^^^^
  File "/home/markmur88/envAPP/lib/python3.13/site-packages/django/core/handlers/exception.py", line 57, in inner
    response = response_for_exception(request, exc)
  File "/home/markmur88/envAPP/lib/python3.13/site-packages/django/core/handlers/exception.py", line 140, in response_for_exception
    response = handle_uncaught_exception(
        request, get_resolver(get_urlconf()), sys.exc_info()
    )
  File "/home/markmur88/envAPP/lib/python3.13/site-packages/django/core/handlers/exception.py", line 181, in handle_uncaught_exception
    return debug.technical_500_response(request, *exc_info)
           ~~~~~~~~~~~~~~~~~~~~~~~~~~~~^^^^^^^^^^^^^^^^^^^^
  File "/home/markmur88/envAPP/lib/python3.13/site-packages/django/views/debug.py", line 69, in technical_500_response
    html = reporter.get_traceback_html()
  File "/home/markmur88/envAPP/lib/python3.13/site-packages/django/views/debug.py", line 428, in get_traceback_html
    c = Context(self.get_traceback_data(), use_l10n=False)
                ~~~~~~~~~~~~~~~~~~~~~~~^^
  File "/home/markmur88/envAPP/lib/python3.13/site-packages/django/views/debug.py", line 411, in get_traceback_data
    c["raising_view_name"] = get_caller(self.request)
                             ~~~~~~~~~~^^^^^^^^^^^^^^
  File "/home/markmur88/envAPP/lib/python3.13/site-packages/django/views/debug.py", line 102, in get_caller
    resolver_match = resolve(request.path)
  File "/home/markmur88/envAPP/lib/python3.13/site-packages/django/urls/base.py", line 25, in resolve
    return get_resolver(urlconf).resolve(path)
           ~~~~~~~~~~~~~~~~~~~~~~~~~~~~~^^^^^^
  File "/home/markmur88/envAPP/lib/python3.13/site-packages/django/urls/resolvers.py", line 666, in resolve
    for pattern in self.url_patterns:
                   ^^^^^^^^^^^^^^^^^
  File "/home/markmur88/envAPP/lib/python3.13/site-packages/django/utils/functional.py", line 47, in __get__
    res = instance.__dict__[self.name] = self.func(instance)
                                         ~~~~~~~~~^^^^^^^^^^
  File "/home/markmur88/envAPP/lib/python3.13/site-packages/django/urls/resolvers.py", line 718, in url_patterns
    patterns = getattr(self.urlconf_module, "urlpatterns", self.urlconf_module)
                       ^^^^^^^^^^^^^^^^^^^
  File "/home/markmur88/envAPP/lib/python3.13/site-packages/django/utils/functional.py", line 47, in __get__
    res = instance.__dict__[self.name] = self.func(instance)
                                         ~~~~~~~~~^^^^^^^^^^
  File "/home/markmur88/envAPP/lib/python3.13/site-packages/django/urls/resolvers.py", line 711, in urlconf_module
    return import_module(self.urlconf_name)
  File "/usr/lib/python3.13/importlib/__init__.py", line 88, in import_module
    return _bootstrap._gcd_import(name[level:], package, level)
           ~~~~~~~~~~~~~~~~~~~~~~^^^^^^^^^^^^^^^^^^^^^^^^^^^^^^
  File "<frozen importlib._bootstrap>", line 1387, in _gcd_import
  File "<frozen importlib._bootstrap>", line 1360, in _find_and_load
  File "<frozen importlib._bootstrap>", line 1331, in _find_and_load_unlocked
  File "<frozen importlib._bootstrap>", line 935, in _load_unlocked
  File "<frozen importlib._bootstrap_external>", line 1026, in exec_module
  File "<frozen importlib._bootstrap>", line 488, in _call_with_frames_removed
  File "/home/markmur88/api_bank_h2/config/urls.py", line 26, in <module>
    from api.gpt4.views import oauth2_authorize, oauth2_callback
  File "/home/markmur88/api_bank_h2/api/gpt4/views.py", line 1319, in <module>
    from .conexion_banco_refactor import (
    ...<3 lines>...
    )
  File "/home/markmur88/api_bank_h2/api/gpt4/conexion_banco_refactor.py", line 203, in <module>
    connector = BankConnector(config=config, logger=logger)
  File "/home/markmur88/api_bank_h2/api/gpt4/conexion_banco_refactor.py", line 102, in __init__
    self._init_client()
    ~~~~~~~~~~~~~~~~~^^
  File "/home/markmur88/api_bank_h2/api/gpt4/conexion_banco_refactor.py", line 110, in _init_client
    dns_bank_raw = self.config.get('DNS_BANCO', required=True)
  File "/home/markmur88/api_bank_h2/api/gpt4/conexion_banco_refactor.py", line 34, in get
    raise ConfigError(f"Missing required config: {name}")
api.gpt4.conexion_banco_refactor.ConfigError: Missing required config: BANK_DNS_BANCO

During handling of the above exception, another exception occurred:

Traceback (most recent call last):
  File "/home/markmur88/envAPP/lib/python3.13/site-packages/gunicorn/workers/sync.py", line 134, in handle
    self.handle_request(listener, req, client, addr)
    ~~~~~~~~~~~~~~~~~~~^^^^^^^^^^^^^^^^^^^^^^^^^^^^^
  File "/home/markmur88/envAPP/lib/python3.13/site-packages/gunicorn/workers/sync.py", line 177, in handle_request
    respiter = self.wsgi(environ, resp.start_response)
  File "/home/markmur88/envAPP/lib/python3.13/site-packages/django/core/handlers/wsgi.py", line 124, in __call__
    response = self.get_response(request)
  File "/home/markmur88/envAPP/lib/python3.13/site-packages/django/core/handlers/base.py", line 140, in get_response
    response = self._middleware_chain(request)
  File "/home/markmur88/envAPP/lib/python3.13/site-packages/django/core/handlers/exception.py", line 57, in inner
    response = response_for_exception(request, exc)
  File "/home/markmur88/envAPP/lib/python3.13/site-packages/django/core/handlers/exception.py", line 140, in response_for_exception
    response = handle_uncaught_exception(
        request, get_resolver(get_urlconf()), sys.exc_info()
    )
  File "/home/markmur88/envAPP/lib/python3.13/site-packages/django/core/handlers/exception.py", line 181, in handle_uncaught_exception
    return debug.technical_500_response(request, *exc_info)
           ~~~~~~~~~~~~~~~~~~~~~~~~~~~~^^^^^^^^^^^^^^^^^^^^
  File "/home/markmur88/envAPP/lib/python3.13/site-packages/django/views/debug.py", line 69, in technical_500_response
    html = reporter.get_traceback_html()
  File "/home/markmur88/envAPP/lib/python3.13/site-packages/django/views/debug.py", line 428, in get_traceback_html
    c = Context(self.get_traceback_data(), use_l10n=False)
                ~~~~~~~~~~~~~~~~~~~~~~~^^
  File "/home/markmur88/envAPP/lib/python3.13/site-packages/django/views/debug.py", line 411, in get_traceback_data
    c["raising_view_name"] = get_caller(self.request)
                             ~~~~~~~~~~^^^^^^^^^^^^^^
  File "/home/markmur88/envAPP/lib/python3.13/site-packages/django/views/debug.py", line 102, in get_caller
    resolver_match = resolve(request.path)
  File "/home/markmur88/envAPP/lib/python3.13/site-packages/django/urls/base.py", line 25, in resolve
    return get_resolver(urlconf).resolve(path)
           ~~~~~~~~~~~~~~~~~~~~~~~~~~~~~^^^^^^
  File "/home/markmur88/envAPP/lib/python3.13/site-packages/django/urls/resolvers.py", line 666, in resolve
    for pattern in self.url_patterns:
                   ^^^^^^^^^^^^^^^^^
  File "/home/markmur88/envAPP/lib/python3.13/site-packages/django/utils/functional.py", line 47, in __get__
    res = instance.__dict__[self.name] = self.func(instance)
                                         ~~~~~~~~~^^^^^^^^^^
  File "/home/markmur88/envAPP/lib/python3.13/site-packages/django/urls/resolvers.py", line 718, in url_patterns
    patterns = getattr(self.urlconf_module, "urlpatterns", self.urlconf_module)
                       ^^^^^^^^^^^^^^^^^^^
  File "/home/markmur88/envAPP/lib/python3.13/site-packages/django/utils/functional.py", line 47, in __get__
    res = instance.__dict__[self.name] = self.func(instance)
                                         ~~~~~~~~~^^^^^^^^^^
  File "/home/markmur88/envAPP/lib/python3.13/site-packages/django/urls/resolvers.py", line 711, in urlconf_module
    return import_module(self.urlconf_name)
  File "/usr/lib/python3.13/importlib/__init__.py", line 88, in import_module
    return _bootstrap._gcd_import(name[level:], package, level)
           ~~~~~~~~~~~~~~~~~~~~~~^^^^^^^^^^^^^^^^^^^^^^^^^^^^^^
  File "<frozen importlib._bootstrap>", line 1387, in _gcd_import
  File "<frozen importlib._bootstrap>", line 1360, in _find_and_load
  File "<frozen importlib._bootstrap>", line 1331, in _find_and_load_unlocked
  File "<frozen importlib._bootstrap>", line 935, in _load_unlocked
  File "<frozen importlib._bootstrap_external>", line 1026, in exec_module
  File "<frozen importlib._bootstrap>", line 488, in _call_with_frames_removed
  File "/home/markmur88/api_bank_h2/config/urls.py", line 26, in <module>
    from api.gpt4.views import oauth2_authorize, oauth2_callback
  File "/home/markmur88/api_bank_h2/api/gpt4/views.py", line 1319, in <module>
    from .conexion_banco_refactor import (
    ...<3 lines>...
    )
  File "/home/markmur88/api_bank_h2/api/gpt4/conexion_banco_refactor.py", line 203, in <module>
    connector = BankConnector(config=config, logger=logger)
  File "/home/markmur88/api_bank_h2/api/gpt4/conexion_banco_refactor.py", line 102, in __init__
    self._init_client()
    ~~~~~~~~~~~~~~~~~^^
  File "/home/markmur88/api_bank_h2/api/gpt4/conexion_banco_refactor.py", line 110, in _init_client
    dns_bank_raw = self.config.get('DNS_BANCO', required=True)
  File "/home/markmur88/api_bank_h2/api/gpt4/conexion_banco_refactor.py", line 34, in get
    raise ConfigError(f"Missing required config: {name}")
api.gpt4.conexion_banco_refactor.ConfigError: Missing required config: BANK_DNS_BANCO
