üìÖ Fecha de ejecuci√≥n: 2025-06-19 10:24:43
üìÑ Script: 00_20_ssl.sh
‚ïê‚ïê‚ïê‚ïê‚ïê‚ïê‚ïê‚ïê‚ïê‚ïê‚ïê‚ïê‚ïê‚ïê‚ïê‚ïê‚ïê‚ïê‚ïê‚ïê‚ïê‚ïê‚ïê‚ïê‚ïê‚ïê‚ïê‚ïê‚ïê‚ïê‚ïê‚ïê‚ïê‚ïê‚ïê‚ïê‚ïê‚ïê‚ïê‚ïê‚ïê‚ïê‚ïê
üåê Levantando entorno local con Gunicorn + SSL en https://0.0.0.0:8443
[2025-06-19 10:24:44 +0200] [159491] [INFO] Starting gunicorn 23.0.0
[2025-06-19 10:24:44 +0200] [159491] [INFO] Listening at: https://0.0.0.0:8443 (159491)
[2025-06-19 10:24:44 +0200] [159491] [INFO] Using worker: sync
[2025-06-19 10:24:44 +0200] [159493] [INFO] Booting worker with pid: 159493
[2025-06-19 10:24:44 +0200] [159494] [INFO] Booting worker with pid: 159494
[2025-06-19 10:24:44 +0200] [159493] [ERROR] Exception in worker process
Traceback (most recent call last):
  File "/home/markmur88/envAPP/lib/python3.13/site-packages/gunicorn/arbiter.py", line 608, in spawn_worker
    worker.init_process()
    ~~~~~~~~~~~~~~~~~~~^^
  File "/home/markmur88/envAPP/lib/python3.13/site-packages/gunicorn/workers/base.py", line 135, in init_process
    self.load_wsgi()
    ~~~~~~~~~~~~~~^^
  File "/home/markmur88/envAPP/lib/python3.13/site-packages/gunicorn/workers/base.py", line 147, in load_wsgi
    self.wsgi = self.app.wsgi()
                ~~~~~~~~~~~~~^^
  File "/home/markmur88/envAPP/lib/python3.13/site-packages/gunicorn/app/base.py", line 66, in wsgi
    self.callable = self.load()
                    ~~~~~~~~~^^
  File "/home/markmur88/envAPP/lib/python3.13/site-packages/gunicorn/app/wsgiapp.py", line 57, in load
    return self.load_wsgiapp()
           ~~~~~~~~~~~~~~~~~^^
  File "/home/markmur88/envAPP/lib/python3.13/site-packages/gunicorn/app/wsgiapp.py", line 47, in load_wsgiapp
    return util.import_app(self.app_uri)
           ~~~~~~~~~~~~~~~^^^^^^^^^^^^^^
  File "/home/markmur88/envAPP/lib/python3.13/site-packages/gunicorn/util.py", line 370, in import_app
    mod = importlib.import_module(module)
  File "/usr/lib/python3.13/importlib/__init__.py", line 88, in import_module
    return _bootstrap._gcd_import(name[level:], package, level)
           ~~~~~~~~~~~~~~~~~~~~~~^^^^^^^^^^^^^^^^^^^^^^^^^^^^^^
  File "<frozen importlib._bootstrap>", line 1387, in _gcd_import
  File "<frozen importlib._bootstrap>", line 1360, in _find_and_load
  File "<frozen importlib._bootstrap>", line 1310, in _find_and_load_unlocked
  File "<frozen importlib._bootstrap>", line 488, in _call_with_frames_removed
  File "<frozen importlib._bootstrap>", line 1387, in _gcd_import
  File "<frozen importlib._bootstrap>", line 1360, in _find_and_load
  File "<frozen importlib._bootstrap>", line 1324, in _find_and_load_unlocked
ModuleNotFoundError: No module named 'config'
[2025-06-19 10:24:44 +0200] [159493] [INFO] Worker exiting (pid: 159493)
[2025-06-19 10:24:44 +0200] [159494] [ERROR] Exception in worker process
Traceback (most recent call last):
  File "/home/markmur88/envAPP/lib/python3.13/site-packages/gunicorn/arbiter.py", line 608, in spawn_worker
    worker.init_process()
    ~~~~~~~~~~~~~~~~~~~^^
  File "/home/markmur88/envAPP/lib/python3.13/site-packages/gunicorn/workers/base.py", line 135, in init_process
    self.load_wsgi()
    ~~~~~~~~~~~~~~^^
  File "/home/markmur88/envAPP/lib/python3.13/site-packages/gunicorn/workers/base.py", line 147, in load_wsgi
    self.wsgi = self.app.wsgi()
                ~~~~~~~~~~~~~^^
  File "/home/markmur88/envAPP/lib/python3.13/site-packages/gunicorn/app/base.py", line 66, in wsgi
    self.callable = self.load()
                    ~~~~~~~~~^^
  File "/home/markmur88/envAPP/lib/python3.13/site-packages/gunicorn/app/wsgiapp.py", line 57, in load
    return self.load_wsgiapp()
           ~~~~~~~~~~~~~~~~~^^
  File "/home/markmur88/envAPP/lib/python3.13/site-packages/gunicorn/app/wsgiapp.py", line 47, in load_wsgiapp
    return util.import_app(self.app_uri)
           ~~~~~~~~~~~~~~~^^^^^^^^^^^^^^
  File "/home/markmur88/envAPP/lib/python3.13/site-packages/gunicorn/util.py", line 370, in import_app
    mod = importlib.import_module(module)
  File "/usr/lib/python3.13/importlib/__init__.py", line 88, in import_module
    return _bootstrap._gcd_import(name[level:], package, level)
           ~~~~~~~~~~~~~~~~~~~~~~^^^^^^^^^^^^^^^^^^^^^^^^^^^^^^
  File "<frozen importlib._bootstrap>", line 1387, in _gcd_import
  File "<frozen importlib._bootstrap>", line 1360, in _find_and_load
  File "<frozen importlib._bootstrap>", line 1310, in _find_and_load_unlocked
  File "<frozen importlib._bootstrap>", line 488, in _call_with_frames_removed
  File "<frozen importlib._bootstrap>", line 1387, in _gcd_import
  File "<frozen importlib._bootstrap>", line 1360, in _find_and_load
  File "<frozen importlib._bootstrap>", line 1324, in _find_and_load_unlocked
ModuleNotFoundError: No module named 'config'
[2025-06-19 10:24:44 +0200] [159494] [INFO] Worker exiting (pid: 159494)
[2025-06-19 10:24:44 +0200] [159495] [INFO] Booting worker with pid: 159495
[2025-06-19 10:24:44 +0200] [159495] [ERROR] Exception in worker process
Traceback (most recent call last):
  File "/home/markmur88/envAPP/lib/python3.13/site-packages/gunicorn/arbiter.py", line 608, in spawn_worker
    worker.init_process()
    ~~~~~~~~~~~~~~~~~~~^^
  File "/home/markmur88/envAPP/lib/python3.13/site-packages/gunicorn/workers/base.py", line 135, in init_process
    self.load_wsgi()
    ~~~~~~~~~~~~~~^^
  File "/home/markmur88/envAPP/lib/python3.13/site-packages/gunicorn/workers/base.py", line 147, in load_wsgi
    self.wsgi = self.app.wsgi()
                ~~~~~~~~~~~~~^^
  File "/home/markmur88/envAPP/lib/python3.13/site-packages/gunicorn/app/base.py", line 66, in wsgi
    self.callable = self.load()
                    ~~~~~~~~~^^
  File "/home/markmur88/envAPP/lib/python3.13/site-packages/gunicorn/app/wsgiapp.py", line 57, in load
    return self.load_wsgiapp()
           ~~~~~~~~~~~~~~~~~^^
  File "/home/markmur88/envAPP/lib/python3.13/site-packages/gunicorn/app/wsgiapp.py", line 47, in load_wsgiapp
    return util.import_app(self.app_uri)
           ~~~~~~~~~~~~~~~^^^^^^^^^^^^^^
  File "/home/markmur88/envAPP/lib/python3.13/site-packages/gunicorn/util.py", line 370, in import_app
    mod = importlib.import_module(module)
  File "/usr/lib/python3.13/importlib/__init__.py", line 88, in import_module
    return _bootstrap._gcd_import(name[level:], package, level)
           ~~~~~~~~~~~~~~~~~~~~~~^^^^^^^^^^^^^^^^^^^^^^^^^^^^^^
  File "<frozen importlib._bootstrap>", line 1387, in _gcd_import
  File "<frozen importlib._bootstrap>", line 1360, in _find_and_load
  File "<frozen importlib._bootstrap>", line 1310, in _find_and_load_unlocked
  File "<frozen importlib._bootstrap>", line 488, in _call_with_frames_removed
  File "<frozen importlib._bootstrap>", line 1387, in _gcd_import
  File "<frozen importlib._bootstrap>", line 1360, in _find_and_load
  File "<frozen importlib._bootstrap>", line 1324, in _find_and_load_unlocked
ModuleNotFoundError: No module named 'config'
[2025-06-19 10:24:44 +0200] [159495] [INFO] Worker exiting (pid: 159495)
[2025-06-19 10:24:44 +0200] [159491] [ERROR] Worker (pid:159493) exited with code 3
[2025-06-19 10:24:44 +0200] [159491] [ERROR] Worker (pid:159494) exited with code 3
Traceback (most recent call last):
  File "/home/markmur88/envAPP/lib/python3.13/site-packages/gunicorn/arbiter.py", line 201, in run
    self.manage_workers()
    ~~~~~~~~~~~~~~~~~~~^^
  File "/home/markmur88/envAPP/lib/python3.13/site-packages/gunicorn/arbiter.py", line 570, in manage_workers
    self.spawn_workers()
    ~~~~~~~~~~~~~~~~~~^^
  File "/home/markmur88/envAPP/lib/python3.13/site-packages/gunicorn/arbiter.py", line 642, in spawn_workers
    time.sleep(0.1 * random.random())
    ~~~~~~~~~~^^^^^^^^^^^^^^^^^^^^^^^
  File "/home/markmur88/envAPP/lib/python3.13/site-packages/gunicorn/arbiter.py", line 241, in handle_chld
    self.reap_workers()
    ~~~~~~~~~~~~~~~~~^^
  File "/home/markmur88/envAPP/lib/python3.13/site-packages/gunicorn/arbiter.py", line 529, in reap_workers
    raise HaltServer(reason, self.WORKER_BOOT_ERROR)
gunicorn.errors.HaltServer: <HaltServer 'Worker failed to boot.' 3>

During handling of the above exception, another exception occurred:

Traceback (most recent call last):
  File "/home/markmur88/envAPP/bin/gunicorn", line 8, in <module>
    sys.exit(run())
             ~~~^^
  File "/home/markmur88/envAPP/lib/python3.13/site-packages/gunicorn/app/wsgiapp.py", line 66, in run
    WSGIApplication("%(prog)s [OPTIONS] [APP_MODULE]", prog=prog).run()
    ~~~~~~~~~~~~~~~~~~~~~~~~~~~~~~~~~~~~~~~~~~~~~~~~~~~~~~~~~~~~~~~~~^^
  File "/home/markmur88/envAPP/lib/python3.13/site-packages/gunicorn/app/base.py", line 235, in run
    super().run()
    ~~~~~~~~~~~^^
  File "/home/markmur88/envAPP/lib/python3.13/site-packages/gunicorn/app/base.py", line 71, in run
    Arbiter(self).run()
    ~~~~~~~~~~~~~~~~~^^
  File "/home/markmur88/envAPP/lib/python3.13/site-packages/gunicorn/arbiter.py", line 228, in run
    self.halt(reason=inst.reason, exit_status=inst.exit_status)
    ~~~~~~~~~^^^^^^^^^^^^^^^^^^^^^^^^^^^^^^^^^^^^^^^^^^^^^^^^^^
  File "/home/markmur88/envAPP/lib/python3.13/site-packages/gunicorn/arbiter.py", line 341, in halt
    self.stop()
    ~~~~~~~~~^^
  File "/home/markmur88/envAPP/lib/python3.13/site-packages/gunicorn/arbiter.py", line 395, in stop
    time.sleep(0.1)
    ~~~~~~~~~~^^^^^
  File "/home/markmur88/envAPP/lib/python3.13/site-packages/gunicorn/arbiter.py", line 241, in handle_chld
    self.reap_workers()
    ~~~~~~~~~~~~~~~~~^^
  File "/home/markmur88/envAPP/lib/python3.13/site-packages/gunicorn/arbiter.py", line 529, in reap_workers
    raise HaltServer(reason, self.WORKER_BOOT_ERROR)
gunicorn.errors.HaltServer: <HaltServer 'Worker failed to boot.' 3>
